## What is an API?

APIs are application programming interfaces that return data on request immediately or after sometime depending upon the code.

API can be either synchronous or asynchronous.

- Synchronous returns the data immediately,wherein the data is requested and waits for it until a value is returned ,it executes from top to bottom of a file or application one by one.

- Aynchronous APIs provide a callback to the requester when the requested resource/value is ready,rather than waiting on a request.

*It may or may not execute synchronously*

*When it encounters asynchronous functions or code ,it keeps running/executing the code which is after it and does not wait for the request to complete. while executing that asynchronous function separately along with the rest of the code,therefore it may happen that it does not execute in a synchronous manner.(One may execute faster than the other)*


## Working with asynchronous APIs

- Take a look at the function we have defined below,`getDone` which is an asynchronous function since it is delaying its execution by 2 sec using the setTimeout function,
*Here,we are getting an error in the console which says "Cannot Read properties of undefined" which is because  the function `todo` demands the value of text immediately which is inside the function `getDone` but it will be executed after 2 seconds,so it will not give the value of text field to `todo` immediately,throwing an error*

```
const getDone=()=>{
  setTimeout(()=>{
    return {text:'Complete code in 2 seconds'}
  },2000)
}
const todo=getDone();
console.log(todo.text);

```


<img width="290" alt="asynccode1" src="https://user-images.githubusercontent.com/74200798/134797152-2c22231a-3a9a-43d3-8fea-ecd9a5ab3b78.PNG">


<img width="554" alt="async1" src="https://user-images.githubusercontent.com/74200798/134797120-68465671-e0ea-43d6-a678-c6a137108a65.PNG">


## Techniques to deal with asynchronous APIs for its proper working:

### 1.Using Callbacks

- **Using only a asynchronous function**

```
const getDone=callback=>{
  setTimeout(()=>{
    callback( {text:'Complete code in 2 seconds'})
  },2000)
}
getDone(todo=>{
  console.log(todo.text)
})
```

Here,instead of a return statement inside the `getDone` function,we are defining a callback.

`getDone` gets a parameter callback and now we use that callback to return the text property inside of it.

Now to call `getDone` with the callback,we define the callback to be `todo` (which is a function)defined below,inside of which we can write any code which is to be executed,here we are consoling **todo.text**

The console log statement is executed when this callback is called inside `getDone` when the 2 sec delay is over & the code inside `setTimeout` is executed and the callback is called and invoked in the `todo` parameter.

<img width="340" alt="asynccode2" src="https://user-images.githubusercontent.com/74200798/134797532-7eacf7db-d87b-46e9-a02f-7f49c791415e.PNG">

<img width="225" alt="async2" src="https://user-images.githubusercontent.com/74200798/134797547-81639c54-7417-42ad-9e4d-5d7b4c0de6c8.PNG">


- **Using a asynchronous function with a executable statement below it(without any delay)**


```
const getDone=callback=>{
  setTimeout(()=>{
    callback( {text:'Complete code in 2 seconds'})
  },2000)
}
getDone(todo=>{
  console.log(todo.text)
})

console.log("i will be outputted first")
```

It is the best example to show how asynchronous APIs work,here although the executable statement is at last,it consoles it first because it has no delay in its execution,after which it executes the `getDone` function which is above it after the 2 second delay,

*Had it been synchronous would have waited for the first function to perform then execute the second statement/function.*

<img width="319" alt="asynccode3" src="https://user-images.githubusercontent.com/74200798/134798233-691ed319-877e-4667-9f82-d50842f79c61.PNG">


<img width="309" alt="async3" src="https://user-images.githubusercontent.com/74200798/134798249-49b6473d-ca43-4a41-aba9-b2260c3c76f0.PNG">



### 2.Using Promises

Once a promise has been called, it means that the calling function continues executing, while the promise is pending until it resolves/rejects, giving the calling function whatever data was being requested.

 

When we use promises to work with asynchronous APIs,this takes two parameters,`resolve` and `reject` ,calling the respective callback functions (passed to then and catch) upon finishing.

We initialize a promise using `new Promise()`.

We can see in this example, the promise checks if the error is true or false, and if that's false, the promise goes to a resolved state (since the resolve callback was called); otherwise, the reject callback is executed, putting the promise in a rejected state. (If none of these functions is called in the execution path, the promise will remain in a pending state).


**In this example,`getDone` is either resolved or rejected.**

we use `.then()` for its execution if it is resolved and `.catch()` if it is rejected.

- Firstly we take error as false for the promise to be resolved,which gives the correct output.


```
const getDone=()=>{
 return new Promise((resolve,reject)=>{
   setTimeout(()=>{
let error=false;
if(!error)
resolve({text:"Completed code without error"})
else
reject()
   },2000)
 })
}

getDone().then(todo=>{
  console.log(todo.text)
})
```

<img width="319" alt="asynccode4" src="https://user-images.githubusercontent.com/74200798/134798523-6996b8a3-c7ad-4cb3-bb6c-00bac7553f9d.PNG">


<img width="546" alt="async4" src="https://user-images.githubusercontent.com/74200798/134798531-f4f34526-bb36-44c6-b735-199518ab39a9.PNG">



- Secondly, we take error as true for the promise to be rejected,which gives the following error.


```
const getDone=()=>{
 return new Promise((resolve,reject)=>{
   setTimeout(()=>{
let error=true;
if(!error)
resolve({text:"Completed code without error"})
else
reject()
   },2000)
 })
}

getDone().then(todo=>{
  console.log(todo.text)
})
```

<img width="310" alt="asynccode5" src="https://user-images.githubusercontent.com/74200798/134798616-87828385-2679-40e0-a9ef-52b372a0eb0e.PNG">

<img width="429" alt="async5" src="https://user-images.githubusercontent.com/74200798/134798643-094971c9-4255-4f90-b056-71edbc7217dd.PNG">


Now to handle this uncaught error,we write the catch block to catch the rejection of promise ,so basically `catch` is invoked when promise is `rejected`,therefore in console,it comes up as error occured rather than uncaught(in promise).


```
const getDone=()=>{
 return new Promise((resolve,reject)=>{
   setTimeout(()=>{
let error=true;
if(!error)
resolve({text:"Completed code without error"})
else
reject()
   },2000)
 })
}

getDone().then(todo=>{
  console.log(todo.text)
})
.catch(error=>{
  console.log("error occured")
})
```

<img width="321" alt="asynccode6" src="https://user-images.githubusercontent.com/74200798/134798734-16dc4948-ab61-437d-a958-991dbe548861.PNG">


<img width="416" alt="async6" src="https://user-images.githubusercontent.com/74200798/134798749-5aa4751c-a07e-4d9d-bb41-0807c7fecf45.PNG">



### 3.Using async/await

- **async/await is built on promises.**

- **Prepending the `async` keyword to any function means that the function will return a promise.**

- **`await` can be put in front of any async promise-based function to pause the code on that line until the promise fulfills.**


- We use async await beacause dealing with promises becomes easier and code becomes more clean and legible.

- We also use async/await specially when we have to deal with multiple promises one after the other.

- Debugging promises is hard but debugging async/await is very easy because to the compiler it's just like synchronous code.




- When we take error as false,thus invoking the `try` block of async/await function.


```
const getDone=()=>{
 return new Promise((resolve,reject)=>{
   setTimeout(()=>{
let error=false;
if(!error)
resolve({text:"Completed code without error"})
else
reject()
   },2000)
 })
}
async function fetchDone(){
  const done=await getDone()
  return done
}
fetchDone().then(done=>{
  console.log(done.text)
})
```

<img width="325" alt="asynccode7" src="https://user-images.githubusercontent.com/74200798/134798968-8616a156-4206-401c-9224-efbd409b4b52.PNG">


<img width="422" alt="async7" src="https://user-images.githubusercontent.com/74200798/134798982-9949144c-eae7-41b4-b830-a0c57f11b22b.PNG">



- When we take error as true,thus invoking the `catch` block(error) of async/await function.


```
const getDone=()=>{
 return new Promise((resolve,reject)=>{
   setTimeout(()=>{
let error=true;
if(!error)
resolve({text:"Completed code without error"})
else
reject()
   },2000)
 })
}
async function fetchDone(){
  try{
    const done=await getDone()
    return done
  }
  catch{
    console.log("error occured")
  }
 
}
fetchDone().then(done=>{
  console.log(done.text)
})
```

<img width="326" alt="asynccode8" src="https://user-images.githubusercontent.com/74200798/134799075-ded02e9b-98f6-4a76-9dea-b5689a7bb34d.PNG">

<img width="562" alt="async8" src="https://user-images.githubusercontent.com/74200798/134799085-905d518c-32eb-4b52-af69-4a43f10ccbbd.PNG">


- If we add the error part under the `catch` block of the `fetchDone` function too,we will not see the uncaught error,message which is given in the console.

```
const getDone=()=>{
 return new Promise((resolve,reject)=>{
   setTimeout(()=>{
let error=true;
if(!error)
resolve({text:"Completed code without error"})
else
reject()
   },2000)
 })
}
async function fetchDone(){
  try{
    const done=await getDone()
    return done
  }
  catch{
    console.log("error occured")
  }
 
}
fetchDone()
.then(done=>{
  console.log(done.text)
})
  .catch(()=>{
    console.log("error occured")
 
})
```

<img width="306" alt="asynccode9" src="https://user-images.githubusercontent.com/74200798/134799202-02dbfccf-414b-4109-b933-2469269bed20.PNG">


<img width="542" alt="async9" src="https://user-images.githubusercontent.com/74200798/134799209-c953bf21-513a-4c0b-b9f9-a7e3fff32326.PNG">




